<robot name="onshape">
<link name="base">
<visual>
<origin xyz="0.2700549758495174868 0.21778927268362430203 -0.094898826431042707097" rpy="1.5707963267948972241 6.1306807814210801304e-46 -1.570796326794896558" />
<geometry>
<mesh filename="package:///body29.stl"/>
</geometry>
<material name="body29_material">
<color rgba="0.79215686274509800047 0.81960784313725487671 0.93333333333333334814 1.0"/>
</material>
</visual>
<collision>
<origin xyz="0.2700549758495174868 0.21778927268362430203 -0.094898826431042707097" rpy="1.5707963267948972241 6.1306807814210801304e-46 -1.570796326794896558" />
<geometry>
<mesh filename="package:///body29.stl"/>
</geometry>
</collision>
<visual>
<origin xyz="0.2700549758495174868 0.21778927268362421876 -0.094898826431042651586" rpy="1.5707963267948972241 -0 -1.570796326794896558" />
<geometry>
<mesh filename="package:///body17.stl"/>
</geometry>
<material name="body17_material">
<color rgba="0.79215686274509800047 0.81960784313725487671 0.93333333333333334814 1.0"/>
</material>
</visual>
<collision>
<origin xyz="0.2700549758495174868 0.21778927268362421876 -0.094898826431042651586" rpy="1.5707963267948972241 -0 -1.570796326794896558" />
<geometry>
<mesh filename="package:///body17.stl"/>
</geometry>
</collision>
<visual>
<origin xyz="0.27005497584951909662 0.21778927268362013869 -0.096588826431040497589" rpy="1.570796326794896336 6.5265560868577627072e-15 -1.570796326794896558" />
<geometry>
<mesh filename="package:///body27.stl"/>
</geometry>
<material name="body27_material">
<color rgba="0.79215686274509800047 0.81960784313725487671 0.93333333333333334814 1.0"/>
</material>
</visual>
<collision>
<origin xyz="0.27005497584951909662 0.21778927268362013869 -0.096588826431040497589" rpy="1.570796326794896336 6.5265560868577627072e-15 -1.570796326794896558" />
<geometry>
<mesh filename="package:///body27.stl"/>
</geometry>
</collision>
<visual>
<origin xyz="0.28822054582599787587 0.183019118827800642 -0.094898826431042318519" rpy="1.5707963267948976682 4.1163702970914931297e-16 -1.6477655836809366185" />
<geometry>
<mesh filename="package:///body38.stl"/>
</geometry>
<material name="body38_material">
<color rgba="0.79215686274509800047 0.81960784313725487671 0.93333333333333334814 1.0"/>
</material>
</visual>
<collision>
<origin xyz="0.28822054582599787587 0.183019118827800642 -0.094898826431042318519" rpy="1.5707963267948976682 4.1163702970914931297e-16 -1.6477655836809366185" />
<geometry>
<mesh filename="package:///body38.stl"/>
</geometry>
</collision>
<inertial>
<origin xyz="0.0048613389509442814229 -0.00053810096798666815811 0.046052375670678352693" rpy="0 0 0"/>
<mass value="11.523951546175686289" />
<inertia ixx="0.11306207940223557407" ixy="-0.00064651918389428903247"  ixz="0.0010537833578081092899" iyy="0.10605446304259993906" iyz="-0.00012981347815160725555" izz="0.1988167712044902613" />
</inertial>
</link>

<link name="link_1">
<visual>
<origin xyz="-0.21778927268362544001 -0.27005497584951732026 0.24530882643104368057" rpy="-1.570796326794896558 9.8607613152626475676e-32 3.0399521804154785451e-17" />
<geometry>
<mesh filename="package:///body40.stl"/>
</geometry>
<material name="body40_material">
<color rgba="0.79215686274509800047 0.81960784313725487671 0.93333333333333334814 1.0"/>
</material>
</visual>
<collision>
<origin xyz="-0.21778927268362544001 -0.27005497584951732026 0.24530882643104368057" rpy="-1.570796326794896558 9.8607613152626475676e-32 3.0399521804154785451e-17" />
<geometry>
<mesh filename="package:///body40.stl"/>
</geometry>
</collision>
<visual>
<origin xyz="-0.23261050214373918399 -0.26075007621057988416 0.24530882643104362506" rpy="-1.570796326794896558 9.8607613152626322409e-32 7.5316094699886844043e-16" />
<geometry>
<mesh filename="package:///body37.stl"/>
</geometry>
<material name="body37_material">
<color rgba="0.79215686274509800047 0.81960784313725487671 0.93333333333333334814 1.0"/>
</material>
</visual>
<collision>
<origin xyz="-0.23261050214373918399 -0.26075007621057988416 0.24530882643104362506" rpy="-1.570796326794896558 9.8607613152626322409e-32 7.5316094699886844043e-16" />
<geometry>
<mesh filename="package:///body37.stl"/>
</geometry>
</collision>
<inertial>
<origin xyz="-0.037059247103240856858 0.023304492622245251421 -0.18019864368158347578" rpy="0 0 0"/>
<mass value="66.027753092333696827" />
<inertia ixx="1.5484299264375800398" ixy="0.090317302087147000034"  ixz="-0.27177119578383013287" iyy="1.6360199493152405292" iyz="0.17071976343647016217" izz="0.78083397933058829032" />
</inertial>
</link>

<link name="link_2">
<visual>
<origin xyz="-0.34451737649731517532 0.53429881338032658711 0.13236381322179846531" rpy="-3.1415926535870215552 -1.0101796838395058487 -1.9746427439807738077e-19" />
<geometry>
<mesh filename="package:///body36.stl"/>
</geometry>
<material name="body36_material">
<color rgba="0.79215686274509800047 0.81960784313725487671 0.93333333333333334814 1.0"/>
</material>
</visual>
<collision>
<origin xyz="-0.34451737649731517532 0.53429881338032658711 0.13236381322179846531" rpy="-3.1415926535870215552 -1.0101796838395058487 -1.9746427439807738077e-19" />
<geometry>
<mesh filename="package:///body36.stl"/>
</geometry>
</collision>
<visual>
<origin xyz="-0.34451740555198595573 0.53429909812420739446 0.15031381322180639715" rpy="-3.1415926535870268843 -1.0101796838395042943 -9.4490739624865382034e-18" />
<geometry>
<mesh filename="package:///body8.stl"/>
</geometry>
<material name="body8_material">
<color rgba="0.79215686274509800047 0.81960784313725487671 0.93333333333333334814 1.0"/>
</material>
</visual>
<collision>
<origin xyz="-0.34451740555198595573 0.53429909812420739446 0.15031381322180639715" rpy="-3.1415926535870268843 -1.0101796838395042943 -9.4490739624865382034e-18" />
<geometry>
<mesh filename="package:///body8.stl"/>
</geometry>
</collision>
<visual>
<origin xyz="-0.34451737649734903712 0.53429881338031748328 0.13723018135095402248" rpy="-3.1415926535870268843 -1.0101796838395045164 -2.6622517295492456724e-16" />
<geometry>
<mesh filename="package:///body22.stl"/>
</geometry>
<material name="body22_material">
<color rgba="0.79215686274509800047 0.81960784313725487671 0.93333333333333334814 1.0"/>
</material>
</visual>
<collision>
<origin xyz="-0.34451737649734903712 0.53429881338031748328 0.13723018135095402248" rpy="-3.1415926535870268843 -1.0101796838395045164 -2.6622517295492456724e-16" />
<geometry>
<mesh filename="package:///body22.stl"/>
</geometry>
</collision>
<inertial>
<origin xyz="0.036029614399853644724 -0.35297441933465356634 -0.068482878560906609855" rpy="0 0 0"/>
<mass value="21.791049228068683163" />
<inertia ixx="1.8853292771415113283" ixy="0.17635251403140955739"  ixz="-0.0078739679513417579204" iyy="0.17821897350127827164" iyz="0.076953599767559582867" izz="1.9566129890889132348" />
</inertial>
</link>

<link name="link_3">
<visual>
<origin xyz="-0.42686285134474810654 -1.3413085176425629808 -0.06429301723949215619" rpy="-8.9672838939822103692e-14 1.0101796838343271023 1.7993510495807852258e-18" />
<geometry>
<mesh filename="package:///body39.stl"/>
</geometry>
<material name="body39_material">
<color rgba="0.79215686274509800047 0.81960784313725487671 0.93333333333333334814 1.0"/>
</material>
</visual>
<collision>
<origin xyz="-0.42686285134474810654 -1.3413085176425629808 -0.06429301723949215619" rpy="-8.9672838939822103692e-14 1.0101796838343271023 1.7993510495807852258e-18" />
<geometry>
<mesh filename="package:///body39.stl"/>
</geometry>
</collision>
<visual>
<origin xyz="-0.42686285134470330904 -1.3413085176425865175 -0.079128813221980662251" rpy="-1.0030948524023691875e-19 1.0101796838343291007 1.2318825343851505544e-18" />
<geometry>
<mesh filename="package:///body23.stl"/>
</geometry>
<material name="body23_material">
<color rgba="0.79215686274509800047 0.81960784313725487671 0.93333333333333334814 1.0"/>
</material>
</visual>
<collision>
<origin xyz="-0.42686285134470330904 -1.3413085176425865175 -0.079128813221980662251" rpy="-1.0030948524023691875e-19 1.0101796838343291007 1.2318825343851505544e-18" />
<geometry>
<mesh filename="package:///body23.stl"/>
</geometry>
</collision>
<inertial>
<origin xyz="0.07729536091517091867 -0.04246757570248862329 -0.082320386937503445268" rpy="0 0 0"/>
<mass value="32.945118318379222444" />
<inertia ixx="0.32857967173000107719" ixy="0.12431284478579390784"  ixz="0.096618322465548162059" iyy="0.48598079062806792683" iyz="-0.05307975568279564571" izz="0.47141899669488657176" />
</inertial>
</link>

<link name="link_4">
<visual>
<origin xyz="-0.43906558579421944843 1.3099522593181485153 -0.024033869618792114142" rpy="2.5655674098249723336 0.48462378981820281032 1.5353811526344933299e-17" />
<geometry>
<mesh filename="package:///body4.stl"/>
</geometry>
<material name="body4_material">
<color rgba="0.79215686274509800047 0.81960784313725487671 0.93333333333333334814 1.0"/>
</material>
</visual>
<collision>
<origin xyz="-0.43906558579421944843 1.3099522593181485153 -0.024033869618792114142" rpy="2.5655674098249723336 0.48462378981820281032 1.5353811526344933299e-17" />
<geometry>
<mesh filename="package:///body4.stl"/>
</geometry>
</collision>
<visual>
<origin xyz="-0.45018900006070128317 1.3067216892145339102 -0.024033869618740821839" rpy="2.5655674098250327297 0.4846237898181897652 6.4305690865642291859e-15" />
<geometry>
<mesh filename="package:///body24.stl"/>
</geometry>
<material name="body24_material">
<color rgba="0.79215686274509800047 0.81960784313725487671 0.93333333333333334814 1.0"/>
</material>
</visual>
<collision>
<origin xyz="-0.45018900006070128317 1.3067216892145339102 -0.024033869618740821839" rpy="2.5655674098250327297 0.4846237898181897652 6.4305690865642291859e-15" />
<geometry>
<mesh filename="package:///body24.stl"/>
</geometry>
</collision>
<visual>
<origin xyz="-0.4390655857943288054 1.3099522593181225361 -0.020303869618739978087" rpy="2.5655674098250171866 0.48462378981817899604 1.0305167817858616191e-16" />
<geometry>
<mesh filename="package:///body28.stl"/>
</geometry>
<material name="body28_material">
<color rgba="0.79215686274509800047 0.81960784313725487671 0.93333333333333334814 1.0"/>
</material>
</visual>
<collision>
<origin xyz="-0.4390655857943288054 1.3099522593181225361 -0.020303869618739978087" rpy="2.5655674098250171866 0.48462378981817899604 1.0305167817858616191e-16" />
<geometry>
<mesh filename="package:///body28.stl"/>
</geometry>
</collision>
<inertial>
<origin xyz="0.10825355173716254276 0.022091488286067939573 -0.26662720680260804107" rpy="0 0 0"/>
<mass value="10.096943531881116485" />
<inertia ixx="0.47084324451825448898" ixy="-0.0079356733107528339144"  ixz="0.11283326459101131189" iyy="0.50815806244261463309" iyz="0.022991058660098165345" izz="0.1013922840950891302" />
</inertial>
</link>

<link name="link_5">
<visual>
<origin xyz="-1.054179099269775044 -1.0662616664126236543 0.27870716293849617795" rpy="-0.16264798233928692839 1.049015660432404573 -1.4734875541177227324e-16" />
<geometry>
<mesh filename="package:///body9.stl"/>
</geometry>
<material name="body9_material">
<color rgba="0.79215686274509800047 0.81960784313725487671 0.93333333333333334814 1.0"/>
</material>
</visual>
<collision>
<origin xyz="-1.054179099269775044 -1.0662616664126236543 0.27870716293849617795" rpy="-0.16264798233928692839 1.049015660432404573 -1.4734875541177227324e-16" />
<geometry>
<mesh filename="package:///body9.stl"/>
</geometry>
</collision>
<visual>
<origin xyz="-1.0541790992697759322 -1.0662616664126234323 0.28450716293849620531" rpy="-0.16264798233928684512 1.0490156604324047951 -3.6414844515904430028e-17" />
<geometry>
<mesh filename="package:///body6.stl"/>
</geometry>
<material name="body6_material">
<color rgba="0.79215686274509800047 0.81960784313725487671 0.93333333333333334814 1.0"/>
</material>
</visual>
<collision>
<origin xyz="-1.0541790992697759322 -1.0662616664126234323 0.28450716293849620531" rpy="-0.16264798233928684512 1.0490156604324047951 -3.6414844515904430028e-17" />
<geometry>
<mesh filename="package:///body6.stl"/>
</geometry>
</collision>
<inertial>
<origin xyz="-0.0056545920389555982474 -0.063607679156253760233 0.086765087009926231132" rpy="0 0 0"/>
<mass value="14.058416968000464919" />
<inertia ixx="0.13839821712010799692" ixy="-0.0063027929893212765802"  ixz="0.0024025865587558397317" iyy="0.06809471181782408844" iyz="0.027192803370498671439" izz="0.11113431168162504759" />
</inertial>
</link>

<link name="link_6">
<visual>
<origin xyz="-0.62048466024742310321 0.74565268222655944896 -0.96884915459576348429" rpy="1.331073014818314304 -0.044240070469656368746 1.0699787272555961658e-16" />
<geometry>
<mesh filename="package:///body33.stl"/>
</geometry>
<material name="body33_material">
<color rgba="0.79215686274509800047 0.81960784313725487671 0.93333333333333334814 1.0"/>
</material>
</visual>
<collision>
<origin xyz="-0.62048466024742310321 0.74565268222655944896 -0.96884915459576348429" rpy="1.331073014818314304 -0.044240070469656368746 1.0699787272555961658e-16" />
<geometry>
<mesh filename="package:///body33.stl"/>
</geometry>
</collision>
<visual>
<origin xyz="-0.62048466020834169843 0.74565268226864622747 -0.96884916588225800105" rpy="1.3310730148183147481 -0.044240070469656132823 -1.0769878211585150083e-16" />
<geometry>
<mesh filename="package:///body34.stl"/>
</geometry>
<material name="body34_material">
<color rgba="0.79215686274509800047 0.81960784313725487671 0.93333333333333334814 1.0"/>
</material>
</visual>
<collision>
<origin xyz="-0.62048466020834169843 0.74565268226864622747 -0.96884916588225800105" rpy="1.3310730148183147481 -0.044240070469656132823 -1.0769878211585150083e-16" />
<geometry>
<mesh filename="package:///body34.stl"/>
</geometry>
</collision>
<visual>
<origin xyz="-0.62048466024742043867 0.74565268222655833874 -0.96884915459576215202" rpy="1.3310730148183149701 -0.044240070469656056495 1.4281371069612188221e-17" />
<geometry>
<mesh filename="package:///body32.stl"/>
</geometry>
<material name="body32_material">
<color rgba="0.79215686274509800047 0.81960784313725487671 0.93333333333333334814 1.0"/>
</material>
</visual>
<collision>
<origin xyz="-0.62048466024742043867 0.74565268222655833874 -0.96884915459576215202" rpy="1.3310730148183149701 -0.044240070469656056495 1.4281371069612188221e-17" />
<geometry>
<mesh filename="package:///body32.stl"/>
</geometry>
</collision>
<visual>
<origin xyz="-0.62048549484268311627 0.74565178349068106378 -0.96884720230860710277" rpy="1.3310730148183165245 -0.04424007046965602874 -2.5894258683083158e-16" />
<geometry>
<mesh filename="package:///body25.stl"/>
</geometry>
<material name="body25_material">
<color rgba="0.79215686274509800047 0.81960784313725487671 0.93333333333333334814 1.0"/>
</material>
</visual>
<collision>
<origin xyz="-0.62048549484268311627 0.74565178349068106378 -0.96884720230860710277" rpy="1.3310730148183165245 -0.04424007046965602874 -2.5894258683083158e-16" />
<geometry>
<mesh filename="package:///body25.stl"/>
</geometry>
</collision>
<visual>
<origin xyz="-0.62048466024742332525 0.74565268222656100328 -0.968849154595762041" rpy="1.3310730148183147481 -0.044240070469656105068 3.4322545447960073937e-18" />
<geometry>
<mesh filename="package:///body2.stl"/>
</geometry>
<material name="body2_material">
<color rgba="0.79215686274509800047 0.81960784313725487671 0.93333333333333334814 1.0"/>
</material>
</visual>
<collision>
<origin xyz="-0.62048466024742332525 0.74565268222656100328 -0.968849154595762041" rpy="1.3310730148183147481 -0.044240070469656105068 3.4322545447960073937e-18" />
<geometry>
<mesh filename="package:///body2.stl"/>
</geometry>
</collision>
<visual>
<origin xyz="-0.62075704971357648088 0.74544436924908397124 -0.96904262074299651886" rpy="1.3310730148183149701 -0.044240070469656118946 -3.1450810516115531235e-16" />
<geometry>
<mesh filename="package:///body31.stl"/>
</geometry>
<material name="body31_material">
<color rgba="0.79215686274509800047 0.81960784313725487671 0.93333333333333334814 1.0"/>
</material>
</visual>
<collision>
<origin xyz="-0.62075704971357648088 0.74544436924908397124 -0.96904262074299651886" rpy="1.3310730148183149701 -0.044240070469656118946 -3.1450810516115531235e-16" />
<geometry>
<mesh filename="package:///body31.stl"/>
</geometry>
</collision>
<visual>
<origin xyz="-0.62075704971357315021 0.74544436924909773801 -0.96904262074299440943" rpy="1.3310730148183131938 -0.044240070469656375685 -8.5023737704297069895e-15" />
<geometry>
<mesh filename="package:///body19.stl"/>
</geometry>
<material name="body19_material">
<color rgba="0.79215686274509800047 0.81960784313725487671 0.93333333333333334814 1.0"/>
</material>
</visual>
<collision>
<origin xyz="-0.62075704971357315021 0.74544436924909773801 -0.96904262074299440943" rpy="1.3310730148183131938 -0.044240070469656375685 -8.5023737704297069895e-15" />
<geometry>
<mesh filename="package:///body19.stl"/>
</geometry>
</collision>
<visual>
<origin xyz="-0.62048466024742243707 0.74565268222655967101 -0.96884915459576237406" rpy="1.3310730148183147481 -0.044240070469656035679 1.5467605925977601838e-16" />
<geometry>
<mesh filename="package:///body16.stl"/>
</geometry>
<material name="body16_material">
<color rgba="0.79215686274509800047 0.81960784313725487671 0.93333333333333334814 1.0"/>
</material>
</visual>
<collision>
<origin xyz="-0.62048466024742243707 0.74565268222655967101 -0.96884915459576237406" rpy="1.3310730148183147481 -0.044240070469656035679 1.5467605925977601838e-16" />
<geometry>
<mesh filename="package:///body16.stl"/>
</geometry>
</collision>
<inertial>
<origin xyz="0.0078136325922326249627 0.0086350104096200135106 -0.057413586760955107047" rpy="0 0 0"/>
<mass value="1.5151635306979434059" />
<inertia ixx="0.0040820619332376482935" ixy="-0.00039576190626691823459"  ixz="-2.8148085324385620676e-05" iyy="0.0040212984848778951866" iyz="-2.6847961807465535564e-05" izz="0.0061433547026207352068" />
</inertial>
</link>

<link name="base_parts">
<visual>
<origin xyz="0.090359188644898655318 -0.54880019891309517188 -0.23138460886146305917" rpy="-1.570796326794896558 -1.570796326794896558 0" />
<geometry>
<mesh filename="package:///base_parts.stl"/>
</geometry>
<material name="base_parts_material">
<color rgba="0.66666666666666662966 0.69803921568627447236 0.76862745098039220171 1.0"/>
</material>
</visual>
<collision>
<origin xyz="0.090359188644898655318 -0.54880019891309517188 -0.23138460886146305917" rpy="-1.570796326794896558 -1.570796326794896558 0" />
<geometry>
<mesh filename="package:///base_parts.stl"/>
</geometry>
</collision>
<inertial>
<origin xyz="-0.00035461707036923777701 1.7012347086620138725e-10 -0.052861555830406581347" rpy="0 0 0"/>
<mass value="6.8521335502091851311" />
<inertia ixx="0.082569068965210379307" ixy="-5.9554088166937217447e-05"  ixz="-3.6594618875459284366e-05" iyy="0.48029298190353536535" iyz="-5.1648095179796252151e-11" izz="0.54063275279522726713" />
</inertial>
</link>

<link name="thread">
<visual>
<origin xyz="5.5511151231257827021e-17 0 -0.36080700000000004435" rpy="-1.570796326794896558 3.991528443434028727e-30 7.8192538199067837875e-32" />
<geometry>
<mesh filename="package:///thread.stl"/>
</geometry>
<material name="thread_material">
<color rgba="0.86666666666666669627 0.90980392156862743835 1 1.0"/>
</material>
</visual>
<collision>
<origin xyz="5.5511151231257827021e-17 0 -0.36080700000000004435" rpy="-1.570796326794896558 3.991528443434028727e-30 7.8192538199067837875e-32" />
<geometry>
<mesh filename="package:///thread.stl"/>
</geometry>
</collision>
<inertial>
<origin xyz="9.8961565194530776464e-07 1.2322328520581388452e-06 -0.36272225113312023259" rpy="0 0 0"/>
<mass value="0.5123007726564026143" />
<inertia ixx="0.024194873888281422797" ixy="2.8515598075830578723e-09"  ixz="2.2904804715842061092e-07" iyy="0.024194865917678946149" iyz="-8.5371196482837724853e-08" izz="2.066728701653512557e-05" />
</inertial>
</link>

<link name="gripper">
<visual>
<origin xyz="0 0.06984999999999996767 -0.037464999999999970548" rpy="3.141592653589793116 5.8669972695259410554e-30 3.3193354883450127264e-31" />
<geometry>
<mesh filename="package:///gripper.stl"/>
</geometry>
<material name="gripper_material">
<color rgba="0.86666666666666669627 0.90980392156862743835 1 1.0"/>
</material>
</visual>
<collision>
<origin xyz="0 0.06984999999999996767 -0.037464999999999970548" rpy="3.141592653589793116 5.8669972695259410554e-30 3.3193354883450127264e-31" />
<geometry>
<mesh filename="package:///gripper.stl"/>
</geometry>
</collision>
<inertial>
<origin xyz="3.6270003643851431379e-07 0.10623756036027126592 -0.051627325488916270269" rpy="0 0 0"/>
<mass value="1.2608594352917319448" />
<inertia ixx="0.011140724458157186955" ixy="6.2595769879666158093e-08"  ixz="-4.9209255468966980449e-09" iyy="0.01098011758401376374" iyz="0.002140957556652902348" izz="0.020753955906728197012" />
</inertial>
</link>

<joint name="8" type="revolute">
<origin xyz="-5.5511151231257827021e-17 -6.6613381477509392425e-16 -0.0081450000000001243627" rpy="2.5121461447381071637e-14 2.3045258115157124947e-14 1.5707963267948983344" />
<parent link="thread" />
<child link="gripper" />
<axis xyz="0 0 1"/>
<limit effort="1" velocity="20" />
<joint_properties friction="0.0"/>
</joint>

<link name="gripper_2">
<visual>
<origin xyz="-1.1102230246251565404e-16 0.06984999999999996767 -0.038100000000000022737" rpy="3.141592653589793116 5.4372984951978033404e-31 -2.0468327726120580613e-31" />
<geometry>
<mesh filename="package:///gripper.stl"/>
</geometry>
<material name="gripper_material">
<color rgba="0.86666666666666669627 0.90980392156862743835 1 1.0"/>
</material>
</visual>
<collision>
<origin xyz="-1.1102230246251565404e-16 0.06984999999999996767 -0.038100000000000022737" rpy="3.141592653589793116 5.4372984951978033404e-31 -2.0468327726120580613e-31" />
<geometry>
<mesh filename="package:///gripper.stl"/>
</geometry>
</collision>
<inertial>
<origin xyz="3.6270003632749201132e-07 0.10623756036027126592 -0.052262325488916322458" rpy="0 0 0"/>
<mass value="1.2608594352917319448" />
<inertia ixx="0.011140724458157186955" ixy="6.2595769879666158093e-08"  ixz="-4.9209255468966980449e-09" iyy="0.01098011758401376374" iyz="0.002140957556652902348" izz="0.020753955906728197012" />
</inertial>
</link>

<joint name="9" type="revolute">
<origin xyz="1.6653345369377348106e-16 -4.5408121707168902503e-14 -0.72531397921818641095" rpy="3.1415926535897686911 -2.3045258115139138918e-14 -1.5707963267948950037" />
<parent link="thread" />
<child link="gripper_2" />
<axis xyz="0 0 1"/>
<limit effort="1" velocity="20" />
<joint_properties friction="0.0"/>
</joint>

<joint name="7" type="revolute">
<origin xyz="0.36591397921818163974 -9.9920072216264088638e-16 -0.097555000000000169358" rpy="-3.1415926535897309435 -1.570796326794871467 0" />
<parent link="base_parts" />
<child link="thread" />
<axis xyz="0 0 1"/>
<limit effort="1" velocity="20" />
<joint_properties friction="0.0"/>
</joint>

<joint name="12" type="revolute">
<origin xyz="1.1102230246251565404e-15 2.1094237467877974268e-15 -0.087034999999998974296" rpy="7.0678692311563371133e-15 1.4609239340019232862e-15 -2.3192071156757125827" />
<parent link="link_6" />
<child link="base_parts" />
<axis xyz="0 0 1"/>
<limit effort="1" velocity="20" />
<joint_properties friction="0.0"/>
</joint>

<joint name="6" type="revolute">
<origin xyz="-0.015990185507606335946 -0.17949918231066652741 0.11660998821190997343" rpy="1.5707963267948978903 -0.74841078888081669085 3.0527449602418612606" />
<parent link="link_5" />
<child link="link_6" />
<axis xyz="0 0 1"/>
<limit effort="1" velocity="20" />
<joint_properties friction="0.0"/>
</joint>

<joint name="5" type="revolute">
<origin xyz="0.12049958683154879391 0.024624981076611707209 -0.63036996585545534977" rpy="1.5707963267948972241 1.0285433207976479864 -1.3692145011401433141" />
<parent link="link_4" />
<child link="link_5" />
<axis xyz="0 0 1"/>
<limit effort="1" velocity="20" />
<joint_properties friction="0.0"/>
</joint>

<joint name="4" type="revolute">
<origin xyz="0.2174298926947178523 -0.11960411114760205464 -0.11998997562072162559" rpy="-1.5707963267950566522 1.3692145011402836463 1.0678907238925263723" />
<parent link="link_3" />
<child link="link_4" />
<axis xyz="0 0 1"/>
<limit effort="1" velocity="20" />
<joint_properties friction="0.0"/>
</joint>

<joint name="3" type="revolute">
<origin xyz="0.082345474851098887648 -0.80700970426109885913 0.024195000000044819544" rpy="-3.1415926535885305704 -5.2560678978283574997e-12 0.047437771585131294216" />
<parent link="link_2" />
<child link="link_3" />
<axis xyz="0 0 1"/>
<limit effort="1" velocity="20" />
<joint_properties friction="0.0"/>
</joint>

<joint name="2" type="revolute">
<origin xyz="-0.1285550888174364359 0.080708027815108884795 -0.28898998695028682571" rpy="1.5707963267939371033 0.096938061838202471687 1.010179683839577125" />
<parent link="link_1" />
<child link="link_2" />
<axis xyz="0 0 1"/>
<limit effort="1" velocity="20" />
<joint_properties friction="0.0"/>
</joint>

<joint name="1" type="revolute">
<origin xyz="6.2450045135165055399e-17 0 0.12997500000000095088" rpy="-3.1415926535897922278 -4.174967405516959139e-16 -0.56061664296056801238" />
<parent link="base" />
<child link="link_1" />
<axis xyz="0 0 1"/>
<limit effort="1" velocity="20" />
<joint_properties friction="0.0"/>
</joint>


</robot>
