<robot name="onshape">
<link name="mobile_robot_base">
<visual>
<origin xyz="-0.10091263104007988649 -0.032650981598644809867 -0.63991732583510785304" rpy="1.570796326794896558 -2.958228394578795584e-31 1.570796326794896336" />
<geometry>
<mesh filename="package:///mobile_robot_base.stl"/>
</geometry>
<material name="mobile_robot_base_material">
<color rgba="0.25098039215686274161 0.25098039215686274161 0.25098039215686274161 1.0"/>
</material>
</visual>
<collision>
<origin xyz="-0.10091263104007988649 -0.032650981598644809867 -0.63991732583510785304" rpy="1.570796326794896558 -2.958228394578795584e-31 1.570796326794896336" />
<geometry>
<mesh filename="package:///mobile_robot_base.stl"/>
</geometry>
</collision>
<inertial>
<origin xyz="-1.6479991885032241328e-08 0.19597576329716812071 -0.21985712943275184661" rpy="0 0 0"/>
<mass value="169.68672195332433716" />
<inertia ixx="36.238356938617698688" ixy="-0.027175606275319466598"  ixz="-7.5219645480806479969e-07" iyy="27.171473916785675584" iyz="0.25116187199146833287" izz="54.066639194435317961" />
</inertial>
</link>

<link name="tire_full">
<visual>
<origin xyz="-0.22862567897382696236 -0.14698848239797968063 0.066364113537296653966" rpy="0.37649586157854292301 -1.5707963267948961139 0" />
<geometry>
<mesh filename="package:///tire.stl"/>
</geometry>
<material name="tire_material">
<color rgba="0.41176470588235292158 0.41176470588235292158 0.41568627450980394356 1.0"/>
</material>
</visual>
<collision>
<origin xyz="-0.22862567897382696236 -0.14698848239797968063 0.066364113537296653966" rpy="0.37649586157854292301 -1.5707963267948961139 0" />
<geometry>
<mesh filename="package:///tire.stl"/>
</geometry>
</collision>
<visual>
<origin xyz="-1.8987384004593803599 -0.30262834302743357728 -0.012700000000000044587" rpy="3.1003698740107185807e-32 2.3890056847893294883e-34 2.4651903288187119056e-32" />
<geometry>
<mesh filename="package:///tire_coupling.stl"/>
</geometry>
<material name="tire_coupling_material">
<color rgba="0.79215686274509800047 0.81960784313725487671 0.93333333333333334814 1.0"/>
</material>
</visual>
<collision>
<origin xyz="-1.8987384004593803599 -0.30262834302743357728 -0.012700000000000044587" rpy="3.1003698740107185807e-32 2.3890056847893294883e-34 2.4651903288187119056e-32" />
<geometry>
<mesh filename="package:///tire_coupling.stl"/>
</geometry>
</collision>
<inertial>
<origin xyz="2.0087174046182637046e-05 -5.1789215858713295921e-06 -0.027484396751771909828" rpy="0 0 0"/>
<mass value="17.832678171432895908" />
<inertia ixx="0.69135573948671757982" ixy="1.0978046876694699121e-05"  ixz="-1.9159335563193548757e-05" iyy="0.6913966993638607228" iyz="4.7946519803599329913e-06" izz="1.2030798507982802814" />
</inertial>
</link>

<joint name="1" type="revolute">
<origin xyz="0.66808885350320790231 -0.3821772333887169526 -0.43525248981564890194" rpy="-2.2204460492505581208e-16 1.5707963267948961139 0" />
<parent link="mobile_robot_base" />
<child link="tire_full" />
<axis xyz="0 0 1"/>
<limit effort="1" velocity="20" />
<joint_properties friction="0.0"/>
</joint>

<link name="tire_full_2">
<visual>
<origin xyz="-1.8987384004593803599 -0.30262834302743352177 -0.012699999999999933564" rpy="-1.2325951644070262941e-32 1.2394922822723108498e-43 2.465190328813960628e-32" />
<geometry>
<mesh filename="package:///tire_coupling.stl"/>
</geometry>
<material name="tire_coupling_material">
<color rgba="0.79215686274509800047 0.81960784313725487671 0.93333333333333334814 1.0"/>
</material>
</visual>
<collision>
<origin xyz="-1.8987384004593803599 -0.30262834302743352177 -0.012699999999999933564" rpy="-1.2325951644070262941e-32 1.2394922822723108498e-43 2.465190328813960628e-32" />
<geometry>
<mesh filename="package:///tire_coupling.stl"/>
</geometry>
</collision>
<visual>
<origin xyz="-0.22862567897383295756 -0.14698848239797790427 0.066364113537297986234" rpy="0.3764958615785334306 -1.5707963267948956698 0" />
<geometry>
<mesh filename="package:///tire.stl"/>
</geometry>
<material name="tire_material">
<color rgba="0.41176470588235292158 0.41176470588235292158 0.41568627450980394356 1.0"/>
</material>
</visual>
<collision>
<origin xyz="-0.22862567897383295756 -0.14698848239797790427 0.066364113537297986234" rpy="0.3764958615785334306 -1.5707963267948956698 0" />
<geometry>
<mesh filename="package:///tire.stl"/>
</geometry>
</collision>
<inertial>
<origin xyz="2.0087174046074941888e-05 -5.1789215860042824246e-06 -0.027484396751772378203" rpy="0 0 0"/>
<mass value="17.832678171432895908" />
<inertia ixx="0.69135573948674455824" ixy="1.0978046876631513852e-05"  ixz="-1.9159335563322517994e-05" iyy="0.69139669936386183302" iyz="4.7946519785722885909e-06" izz="1.2030798507983286871" />
</inertial>
</link>

<joint name="2" type="revolute">
<origin xyz="0.67508885350320846364 0.78740000000000032188 -0.43631658542133933132" rpy="-8.8817841970014357335e-16 1.5707963267948961139 0" />
<parent link="mobile_robot_base" />
<child link="tire_full_2" />
<axis xyz="0 0 1"/>
<limit effort="1" velocity="20" />
<joint_properties friction="0.0"/>
</joint>

<link name="tire_full_3">
<visual>
<origin xyz="-1.8987384004593803599 -0.30262834302743352177 -0.012699999999999933564" rpy="1.2325951644066970437e-32 2.3868601381595175148e-43 7.3955709866400145392e-32" />
<geometry>
<mesh filename="package:///tire_coupling.stl"/>
</geometry>
<material name="tire_coupling_material">
<color rgba="0.79215686274509800047 0.81960784313725487671 0.93333333333333334814 1.0"/>
</material>
</visual>
<collision>
<origin xyz="-1.8987384004593803599 -0.30262834302743352177 -0.012699999999999933564" rpy="1.2325951644066970437e-32 2.3868601381595175148e-43 7.3955709866400145392e-32" />
<geometry>
<mesh filename="package:///tire_coupling.stl"/>
</geometry>
</collision>
<visual>
<origin xyz="-0.22862567897383206938 -0.1469884823979760724 0.066364113537298874412" rpy="0.37649586157853209833 -1.5707963267948958919 0" />
<geometry>
<mesh filename="package:///tire.stl"/>
</geometry>
<material name="tire_material">
<color rgba="0.41176470588235292158 0.41176470588235292158 0.41568627450980394356 1.0"/>
</material>
</visual>
<collision>
<origin xyz="-0.22862567897383206938 -0.1469884823979760724 0.066364113537298874412" rpy="0.37649586157853209833 -1.5707963267948958919 0" />
<geometry>
<mesh filename="package:///tire.stl"/>
</geometry>
</collision>
<inertial>
<origin xyz="2.0087174046613410897e-05 -5.1789215857215877196e-06 -0.027484396751772541267" rpy="0 0 0"/>
<mass value="17.832678171432895908" />
<inertia ixx="0.69135573948674922118" ixy="1.0978046870490336943e-05"  ixz="-1.9159335563300457868e-05" iyy="0.69139669936385161897" iyz="4.7946519802102004361e-06" izz="1.2030798507983540002" />
</inertial>
</link>

<joint name="3" type="revolute">
<origin xyz="-0.67508885350320302354 -0.38099999999999994982 -0.43631658542133955336" rpy="7.7715611723761263513e-16 -1.5707963267948927832 0" />
<parent link="mobile_robot_base" />
<child link="tire_full_3" />
<axis xyz="0 0 1"/>
<limit effort="1" velocity="20" />
<joint_properties friction="0.0"/>
</joint>

<link name="tire_full_4">
<visual>
<origin xyz="-1.8987384004593803599 -0.30262834302743357728 -0.012699999999999933564" rpy="6.351795451943517973e-33 -1.0848781896794382045e-32 -2.4651903288154188542e-32" />
<geometry>
<mesh filename="package:///tire_coupling.stl"/>
</geometry>
<material name="tire_coupling_material">
<color rgba="0.79215686274509800047 0.81960784313725487671 0.93333333333333334814 1.0"/>
</material>
</visual>
<collision>
<origin xyz="-1.8987384004593803599 -0.30262834302743357728 -0.012699999999999933564" rpy="6.351795451943517973e-33 -1.0848781896794382045e-32 -2.4651903288154188542e-32" />
<geometry>
<mesh filename="package:///tire_coupling.stl"/>
</geometry>
</collision>
<visual>
<origin xyz="-0.22862567897383229143 -0.14698848239797812631 0.066364113537298208279" rpy="0.37649586157853537349 -1.5707963267948956698 0" />
<geometry>
<mesh filename="package:///tire.stl"/>
</geometry>
<material name="tire_material">
<color rgba="0.41176470588235292158 0.41176470588235292158 0.41568627450980394356 1.0"/>
</material>
</visual>
<collision>
<origin xyz="-0.22862567897383229143 -0.14698848239797812631 0.066364113537298208279" rpy="0.37649586157853537349 -1.5707963267948956698 0" />
<geometry>
<mesh filename="package:///tire.stl"/>
</geometry>
</collision>
<inertial>
<origin xyz="2.0087174046424946067e-05 -5.1789215860059468444e-06 -0.027484396751772215139" rpy="0 0 0"/>
<mass value="17.832678171432895908" />
<inertia ixx="0.69135573948674444722" ixy="1.0978046876616711104e-05"  ixz="-1.9159335563393407875e-05" iyy="0.69139669936386161098" iyz="4.7946519806168245317e-06" izz="1.2030798507983286871" />
</inertial>
</link>

<joint name="4" type="revolute">
<origin xyz="-0.66808885350320235119 0.78857723338871665852 -0.43525248981564912398" rpy="8.8817841970014357335e-16 -1.5707963267948958919 0" />
<parent link="mobile_robot_base" />
<child link="tire_full_4" />
<axis xyz="0 0 1"/>
<limit effort="1" velocity="20" />
<joint_properties friction="0.0"/>
</joint>


</robot>
